Workbook

Sheet Information
A1: API contract workbook (HIMS)
A3: What is an API? | B3: An API is a set of fixed doors into a program. A screen uses a door to ask the server for data or for an action. The server does the work. Then the server sends back an answer. The screen never opens the database.
A4: Example | B4: A patient goes to the reception window of a hospital. The patient gives a filled form. The staff checks the records room. Then the staff gives back a token slip. The window is the API. The form is the request. The records room is the database. The token slip is the response.
A5: Example in HIMS | B5: The billing clerk records a UPI payment of 500 on bill 1042. The screen sends: POST /api/v1/billing/bills/1042/payments { "amount_paid": 500.00, "payment_mode": "UPI", "reference_number": "UPI88231" } The server sends back: 201 Created { "payment_id": 77, "bill_status": "Partly Paid", "outstanding_amount": 300.00 } If the amount is more than the balance, the server sends back: 422 { "error_code": "AMOUNT_EXCEEDS_BALANCE", "message": "...", "field": "amount_paid" }
A6: What is an API contract? | B6: An API contract is a written agreement for each endpoint. It tells: the method, the path, the roles, the request fields, the reply, and the errors. The screen team and the server team both obey it.
A7: Why use an API contract? | B7: 1) The screen team and the server team can work at the same time. 2) All teams use the same field names. Example: amount_paid, not amount. 3) Testers write one test for each success reply and one test for each error. 4) Each endpoint traces to an FR, a use case and a test case. Then the RTM status can change to Designed.
A8: Input documents | B8: Keep these documents open: SRS (FR and BR), Use case specifications (UC-01 to UC-15), ER model (table and column names), State machines workbook (SM-01 to SM-07), RTM.
A9: How to use this workbook | B9: 1) Do Step 1 to Step 9 in sequence. 2) Do one use case at a time. 3) Read the 'How' line at the top of each sheet. 4) Look at the green example rows. The examples follow UC-10 (take payment) and UC-03 (book appointment). 5) Write your rows in the yellow cells. 6) Copy each finished endpoint into the 'My Contract' sheet. 7) Compare your work with the Solution sheets.
A10: Steps | B10: Step 1 Actions: find what each screen asks the server. Step 2 Method: select GET, POST, PUT, PATCH or DELETE. Step 3 Path: write the address of the endpoint. Step 4 Roles: write who can use the endpoint. Step 5 Request: write the fields that the screen sends. Step 6 Reply: write the status code and the fields that the server sends back. Step 7 Errors: write each error that can occur. Step 8 Trace: link each endpoint to FR, UC, BR, SM and test case. Step 9 Check: do the final checks.
A11: Reference sheets | B11: Ref Standards: the rules that apply to all endpoints. Ref Codes: the status codes and what they mean.
A12: Solution sheets | B12: Sol Endpoints: the complete API contract (all endpoints, Modules A to F). Sol Errors: all error codes and their meaning. Sol FR Coverage: a check that each FR has one or more endpoints.
A14: Words in this workbook
A15: Word | B15: Meaning
A16: API | B16: Application Programming Interface. The set of endpoints of the server.
A17: Endpoint | B17: One door of the API. One method plus one path. Example: POST /api/v1/appointments.
A18: Server | B18: The FastAPI program. It does the work and talks to the database.
A19: Method | B19: The type of action: GET, POST, PUT, PATCH or DELETE.
A20: Path | B20: The address of the endpoint. Example: /api/v1/billing/bills/{bill_id}.
A21: Request | B21: The data that the screen sends to the server.
A22: Response (reply) | B22: The data that the server sends back to the screen.
A23: Status code | B23: A number in the reply that tells the result. Example: 201 = a new record is made.
A24: JSON | B24: The text format of the request and the reply. Example: { "amount_paid": 500.00 }.
A25: Role | B25: The job of the user. Example: Doctor, Billing Clerk.
A26: Token | B26: A key that the server gives after login. The screen sends it with each request.
A27: Field | B27: One item of data. Use the ER column name. Example: appointment_date.
A29: Legend
B30: Column name. Do not change.
B31: Example row. Do not change. Use it as a model.
B32: You write here.

Sheet Ref Standards
A1: Reference: standards for all endpoints
A2: How: Obey these rules in each endpoint.
A3: Standard | B3: Rule | C3: Example
A4: Base path | B4: Start each path with /api/v1/. v1 is the version. A change that breaks the screens needs v2. | C4: /api/v1/patients/search
A5: Format | B5: Send JSON. Get JSON. Use the header Content-Type: application/json. Only file upload uses multipart/form-data. | C5: A2 patient documents
A6: Login token | B6: Send Authorization: Bearer <token> with each request. Login, forgot password and reset password need no token. | C6: Authorization: Bearer eyJhbGciOi...
A7: Role check | B7: The server checks the role on each request (NFR-08). The server writes each denied attempt to AUDIT_LOG. | C7: E9: Billing Clerk only
A8: No delete | B8: Never delete patient, clinical or money rows (NFR-14). Set is_active to false or use a Cancelled status. | C8: F10b: no DELETE
A9: Field names | B9: Use snake_case. Use the ER column name exactly. | C9: appointment_date, not apptDate
A10: IDs | B10: Paths use the internal key (patient_id, bill_id). Replies also send the visible number (mrn, bill_no). Screens show the visible number only. | C10: mrn: MRN-0001049
A11: Dates and times | B11: Use ISO 8601 with the time zone. A date alone is YYYY-MM-DD. | C11: 2026-10-05T10:30:00+05:30
A12: Money | B12: Use a decimal with 2 places. The database stores NUMERIC(12,2). Never use a float (NFR-12). | C12: "amount_paid": 500.00
A13: Status values | B13: Use the state machine values exactly. Use the same spelling and capital letters. | C13: Partly Paid, Sample Collected
A14: Status moves | B14: Only the server moves a status. It allows only the moves in SM-01 to SM-07. Other moves get 409 ILLEGAL_STATE_MOVE. | C14: Draft -> Paid is refused
... A18: Table owner | B18: Only the module that owns a table writes it. Other modules call the service of that module. | C18: Module D calls Module E to add a lab charge

Sheet Ref Codes
A1: Reference: status codes
A2: How: Use this table to select the status code in Step 6 and Step 7.
A3: Code | B3: Name | C3: Meaning | D3: Examples
A4: 200 | B4: OK | C4: The server found the data, or the change or status move is complete. | D4: Get a bill. Finalise a bill.
A5: 201 | B5: Created | C5: The server made a new record. The reply has the new record. | D5: Book an appointment. Record a payment.
A6: 204 | B6: No Content | C6: The action is complete. The reply has no data. | D6: Logout. Change password.
A7: 400 | B7: Bad Request | C7: The request is not correct in form. Example: a date is not a date. | D7: INVALID_DATE, INVALID_DATE_RANGE
A8: 401 | B8: Unauthorized | C8: You are not logged in, the token is expired, or the password is wrong. | D8: NOT_AUTHENTICATED, TOKEN_EXPIRED, INVALID_CREDENTIALS, ACCOUNT_LOCKED
A9: 403 | B9: Forbidden | C9: You are logged in, but your role cannot use this endpoint. | D9: ROLE_NOT_ALLOWED
A10: 404 | B10: Not Found | C10: No record has this ID. | D10: PATIENT_NOT_FOUND, BILL_NOT_FOUND
A11: 409 | B11: Conflict | C11: The request does not agree with the current state or with another record. | D11: ILLEGAL_STATE_MOVE, SLOT_ALREADY_BOOKED, DUPLICATE_USERNAME
A12: 422 | B12: Unprocessable | C12: The request has the correct form, but a field rule or a business rule stops it. | D12: FIELD_REQUIRED, AMOUNT_EXCEEDS_BALANCE

Sheet API Endpoints
A1: The complete HIMS API contract (Modules A to F)
A3: Endpoint ID | B3: Module | C3: Method | D3: Path | E3: Allowed roles | F3: What it does | G3: Request fields (* = required) | H3: Success code | I3: Reply fields | J3: Errors | K3: FR | L3: Use case | M3: BR | N3: SM move | O3: Test case
A4: A1 | B4: A | C4: POST | D4: /api/v1/patients | E4: Receptionist | F4: Register a new patient. Warn when a possible duplicate exists. | G4: full_name*, gender*, date_of_birth*, phone*, id_document_type* (Aadhar | Ration Card), id_document_number*, blood_group, address, insurer_name, insurance_policy_number, confirm_not_duplicate (default false) | H4: 201 | I4: patient_id, mrn, full_name, age, is_active | J4: 422 FIELD_REQUIRED; 409 POSSIBLE_DUPLICATE_PATIENT; 409 AADHAR_ALREADY_REGISTERED | K4: FR-A-001, FR-A-002 | L4: UC-01 | M4: BR-A-01, BR-A-02 | N4: - | O4: TC-A-001, TC-A-002
A5: A2 | B5: A | C5: POST | D5: /api/v1/patients/{patient_id}/documents | E5: Receptionist | F5: Upload the patient photo and the ID document scan. | G5: multipart/form-data: photo_file, id_document_file (jpg, png or pdf; 2 MB maximum) | H5: 200 | I5: patient_id, photo_file, id_document_file | J5: 404 PATIENT_NOT_FOUND; 422 FILE_TYPE_NOT_ALLOWED; 422 FILE_TOO_LARGE | K5: FR-A-001 | L5: UC-01 | M5: BR-A-01 | N5: - | O5: TC-A-001
A6: A3 | B6: A | C6: GET | D6: /api/v1/patients/search | E6: Receptionist, Doctor, Billing Clerk, Admin | F6: Find patients by MRN (old MRNs too), name, phone or ID number. | G6: Query: mrn, full_name, phone, id_document_number (one or more); page, size | H6: 200 | I6: items [patient_id, mrn, full_name, gender, date_of_birth, phone, matched_on_old_mrn], total, page, size | J6: 400 SEARCH_VALUE_REQUIRED | K6: FR-A-003 | L6: UC-02 | M6: BR-A-03 | N6: - | O6: TC-A-003
A7: A4 | B7: A | C7: GET | D7: /api/v1/patients/{patient_id} | E7: Receptionist, Doctor, Billing Clerk, Admin | F7: Show the details of one patient. | G7: None | H7: 200 | I7: All PATIENT columns, age (calculated, not stored) | J7: 404 PATIENT_NOT_FOUND | K7: FR-A-003 | L7: UC-02 | M7: BR-A-03 | N7: - | O7: TC-A-003
A8: A5 | B8: A | C8: GET | D8: /api/v1/patients/{patient_id}/summary | E8: Doctor, Receptionist, Admin | F8: Show the patient summary. The server removes the sections that the role cannot see. | G8: None | H8: 200 | I8: patient, contacts, visits, consultation_summaries, lab_results (Verified only), bills | J8: 403 ROLE_NOT_ALLOWED; 404 PATIENT_NOT_FOUND | K8: FR-A-004, FR-A-007 | L8: UC-02 | M8: BR-A-04, BR-A-07 | N8: SM-05 | O8: TC-A-004, TC-A-007
A9: A6 | B9: A | C9: PATCH | D9: /api/v1/patients/{patient_id} | E9: Receptionist | F9: Change the patient details. MRN and patient_id cannot change. | G9: Any editable field from A1 | H9: 200 | I9: Updated patient | J9: 422 FIELD_NOT_EDITABLE; 404 PATIENT_NOT_FOUND | K9: FR-A-005 | L9: System rule | M9: BR-A-05 | N9: - | O9: TC-A-005
A10: A7 | B10: A | C10: GET | D10: /api/v1/patients/{patient_id}/history | E10: Admin | F10: Show who changed the patient record, what changed, and when. | G10: Query: page, size | H10: 200 | I10: items [changed_field, old_value, new_value, performed_by, performed_at], total | J10: 404 PATIENT_NOT_FOUND | K10: FR-A-005 | L10: System rule | M10: BR-A-05 | N10: - | O10: TC-A-005
A11: A8 | B11: A | C11: POST | D11: /api/v1/patients/{patient_id}/contacts | E11: Receptionist | F11: Add an emergency contact or next of kin. | G11: contact_name*, contact_number*, relationship | H11: 201 | I11: patient_contact_id, contact_name, relationship, contact_number | J11: 422 FIELD_REQUIRED; 404 PATIENT_NOT_FOUND | K11: FR-A-006 | L11: UC-01 | M11: BR-A-06 | N11: - | O11: TC-A-006
A12: A9 | B12: A | C12: PATCH | D12: /api/v1/patients/{patient_id}/contacts/{patient_contact_id} | E12: Receptionist | F12: Change or deactivate a contact. | G12: contact_name, contact_number, relationship, is_active | H12: 200 | I12: Updated contact | J12: 404 CONTACT_NOT_FOUND | K12: FR-A-006 | L12: UC-01 | M12: BR-A-06 | N12: - | O12: TC-A-006
A13: A10 | B13: A | C13: POST | D13: /api/v1/patients/{patient_id}/merge | E13: Receptionist | F13: Merge a confirmed duplicate into this patient. Keep the old MRN for search. | G13: duplicate_patient_id*, merge_reason* | H13: 200 | I13: patient_id, mrn, old_mrn, moved_visits, moved_appointments, moved_bills | J13: 409 SAME_PATIENT; 422 REASON_REQUIRED; 404 PATIENT_NOT_FOUND | K13: FR-A-008 | L13: UC-01 | M13: BR-A-08 | N13: - | O13: TC-A-008
A14: B1a | B14: B | C14: POST | D14: /api/v1/appointments/departments | E14: Admin | F14: Add a department. | G14: department_name* | H14: 201 | I14: department_id, department_name, is_active | J14: 422 FIELD_REQUIRED; 409 DUPLICATE_NAME | K14: FR-B-001 | L14: UC-13 | M14: BR-B-01 | N14: SM-03 move 1 | O14: TC-B-001
... A92: F15 | B92: F | C92: GET | D92: /api/v1/admin/audit-log | E92: Admin | F92: Search the audit trail. | G92: Query: entity_name, entity_id, performed_by, from_date, to_date, page, size | H92: 200 | I92: items [entity_name, entity_id, action, changed_field, old_value, new_value, performed_by, performed_at], total | J92: None | K92: FR-A-005 | L92: System rule | M92: BR-A-05 | N92: - | O92: TC-A-005
A94: Totals
A95: All endpoints | D95: =COUNTA(A4:A92) -> 89
A96: Module A | D96: =COUNTIF(B4:B92,"A") -> 10
A97: Module B | D97: =COUNTIF(B4:B92,"B") -> 20
A98: Module C | D98: =COUNTIF(B4:B92,"C") -> 15
A99: Module D | D99: =COUNTIF(B4:B92,"D") -> 10
A100: Module E | D100: =COUNTIF(B4:B92,"E") -> 15
A101: Module F | D101: =COUNTIF(B4:B92,"F") -> 19

Sheet Errors
A1: All error codes
A3: error_code | B3: Status code | C3: Meaning | D3: Used by (Endpoint ID)
A4: INVALID_DATE | B4: 400 | C4: The date is missing or not in the format YYYY-MM-DD. | D4: B12, E5, E14
A5: INVALID_DATE_RANGE | B5: 400 | C5: from_date is after to_date, or a date is missing. | D5: F11
A6: SEARCH_VALUE_REQUIRED | B6: 400 | C6: The search has no value. Give one or more search values. | D6: A3
A7: ACCOUNT_INACTIVE | B7: 401 | C7: The account is Inactive. Speak to the Admin. | D7: F1
A8: ACCOUNT_LOCKED | B8: 401 | C8: The account is locked for 15 minutes after 5 incorrect passwords. | D8: F1
A9: INVALID_CREDENTIALS | B9: 401 | C9: The username or the password is not correct. | D9: F1, F4
A10: NOT_AUTHENTICATED | B10: 401 | C10: You are not logged in, or your token is not valid. | D10: F2, F3
A11: TOKEN_EXPIRED | B11: 401 | C11: Your login token is expired. Log in again. | D11: All endpoints
A12: NOT_AUTHORISED_TO_VERIFY | B12: 403 | C12: Only a senior or authorised lab technician can verify a result. | D12: D5
A13: NOT_LINKED_TO_DOCTOR | B13: 403 | C13: Your login is not linked to a doctor record. | D13: C1
A14: ROLE_NOT_ALLOWED | B14: 403 | C14: Your role cannot use this endpoint. The server writes this attempt to AUDIT_LOG. | D14: A5, F14
... A86: VISIT_TYPE_INVALID | B86: 422 | C86: The visit type is not Walk-in or Emergency. | D86: B13

Sheet FR Coverage
A1: FR coverage check
A3: FR | B3: FR name | C3: Endpoints | D3: Result
A4: FR-A-001 | B4: Register New Patient | C4: =COUNTIF('API Endpoints'!$K$4:$K$92,"*FR-A-001*") -> 2 | D4: =IF(C4>0,"Covered","Gap") -> Covered
A5: FR-A-002 | B5: Check for Possible Duplicate Patient | C5: =COUNTIF('API Endpoints'!$K$4:$K$92,"*FR-A-002*") -> 1 | D5: =IF(C5>0,"Covered","Gap") -> Covered
A6: FR-A-003 | B6: Search Patient | C6: =COUNTIF('API Endpoints'!$K$4:$K$92,"*FR-A-003*") -> 2 | D6: =IF(C6>0,"Covered","Gap") -> Covered
A7: FR-A-004 | B7: View Patient Summary | C7: =COUNTIF('API Endpoints'!$K$4:$K$92,"*FR-A-004*") -> 1 | D7: =IF(C7>0,"Covered","Gap") -> Covered
A8: FR-A-005 | B8: Track Patient Record Changes | C8: =COUNTIF('API Endpoints'!$K$4:$K$92,"*FR-A-005*") -> 3 | D8: =IF(C8>0,"Covered","Gap") -> Covered
A9: FR-A-006 | B9: Capture Emergency Contact / Next of Kin | C9: =COUNTIF('API Endpoints'!$K$4:$K$92,"*FR-A-006*") -> 2 | D9: =IF(C9>0,"Covered","Gap") -> Covered
A10: FR-A-007 | B10: Role-Based Patient Information Access | C10: =COUNTIF('API Endpoints'!$K$4:$K$92,"*FR-A-007*") -> 1 | D10: =IF(C10>0,"Covered","Gap") -> Covered
A11: FR-A-008 | B11: Merge Confirmed Duplicate Patient | C11: =COUNTIF('API Endpoints'!$K$4:$K$92,"*FR-A-008*") -> 1 | D11: =IF(C11>0,"Covered","Gap") -> Covered
A12: FR-B-001 | B12: Configure Departments, Doctors and Time Slots | C12: =COUNTIF('API Endpoints'!$K$4:$K$92,"*FR-B-001*") -> 8 | D12: =IF(C12>0,"Covered","Gap") -> Covered
A13: FR-B-002 | B13: Book Appointment | C13: =COUNTIF('API Endpoints'!$K$4:$K$92,"*FR-B-002*") -> 2 | D13: =IF(C13>0,"Covered","Gap") -> Covered
A14: FR-B-003 | B14: Track Appointment Status | C14: =COUNTIF('API Endpoints'!$K$4:$K$92,"*FR-B-003*") -> 3 | D14: =IF(C14>0,"Covered","Gap") -> Covered
A15: FR-B-004 | B15: Reschedule or Cancel Appointment | C15: =COUNTIF('API Endpoints'!$K$4:$K$92,"*FR-B-004*") -> 3 | D15: =IF(C15>0,"Covered","Gap") -> Covered
A16: FR-B-005 | B16: Create Visit Record on Check-in | C16: =COUNTIF('API Endpoints'!$K$4:$K$92,"*FR-B-005*") -> 2 | D16: =IF(C16>0,"Covered","Gap") -> Covered
A17: FR-B-006 | B17: View Daily Appointment List | C17: =COUNTIF('API Endpoints'!$K$4:$K$92,"*FR-B-006*") -> 1 | D17: =IF(C17>0,"Covered","Gap") -> Covered
A18: FR-B-007 | B18: Create Walk-in / Emergency Visit | C18: =COUNTIF('API Endpoints'!$K$4:$K$92,"*FR-B-007*") -> 1 | D18: =IF(C18>0,"Covered","Gap") -> Covered
A19: FR-C-001 | B19: Doctor Daily Appointment List | C19: =COUNTIF('API Endpoints'!$K$4:$K$92,"*FR-C-001*") -> 4 | D19: =IF(C19>0,"Covered","Gap") -> Covered
A20: FR-C-002 | B20: Record Diagnosis | C20: =COUNTIF('API Endpoints'!$K$4:$K$92,"*FR-C-002*") -> 2 | D20: =IF(C20>0,"Covered","Gap") -> Covered
A21: FR-C-003 | B21: Generate Prescription | C21: =COUNTIF('API Endpoints'!$K$4:$K$92,"*FR-C-003*") -> 3 | D21: =IF(C21>0,"Covered","Gap") -> Covered
A22: FR-C-004 | B22: Record Medical/Surgical Procedure Recommendation | C22: =COUNTIF('API Endpoints'!$K$4:$K$92,"*FR-C-004*") -> 2 | D22: =IF(C22>0,"Covered","Gap") -> Covered
A23: FR-C-005 | B23: View Patient Medical History | C23: =COUNTIF('API Endpoints'!$K$4:$K$92,"*FR-C-005*") -> 1 | D23: =IF(C23>0,"Covered","Gap") -> Covered
A24: FR-C-006 | B24: Record Long-term Conditions | C24: =COUNTIF('API Endpoints'!$K$4:$K$92,"*FR-C-006*") -> 1 | D24: =IF(C24>0,"Covered","Gap") -> Covered
A25: FR-C-007 | B25: Order Laboratory Tests | C25: =COUNTIF('API Endpoints'!$K$4:$K$92,"*FR-C-007*") -> 1 | D25: =IF(C25>0,"Covered","Gap") -> Covered
A26: FR-C-008 | B26: View Laboratory Reports | C26: =COUNTIF('API Endpoints'!$K$4:$K$92,"*FR-C-008*") -> 1 | D26: =IF(C26>0,"Covered","Gap") -> Covered
A27: FR-D-001 | B27: View Pending Laboratory Test Requests | C27: =COUNTIF('API Endpoints'!$K$4:$K$92,"*FR-D-001*") -> 2 | D27: =IF(C27>0,"Covered","Gap") -> Covered
A28: FR-D-002 | B28: Update Laboratory Test Status | C28: =COUNTIF('API Endpoints'!$K$4:$K$92,"*FR-D-002*") -> 2 | D28: =IF(C28>0,"Covered","Gap") -> Covered
A29: FR-D-003 | B29: Record Laboratory Test Results | C29: =COUNTIF('API Endpoints'!$K$4:$K$92,"*FR-D-003*") -> 1 | D29: =IF(C29>0,"Covered","Gap") -> Covered
A30: FR-D-004 | B30: Flag Abnormal Laboratory Results | C30: =COUNTIF('API Endpoints'!$K$4:$K$92,"*FR-D-004*") -> 1 | D30: =IF(C30>0,"Covered","Gap") -> Covered
A31: FR-D-005 | B31: Generate Laboratory Report | C31: =COUNTIF('API Endpoints'!$K$4:$K$92,"*FR-D-005*") -> 2 | D31: =IF(C31>0,"Covered","Gap") -> Covered
A32: FR-D-006 | B32: Forward Laboratory Charges to Billing | C32: =COUNTIF('API Endpoints'!$K$4:$K$92,"*FR-D-006*") -> 1 | D32: =IF(C32>0,"Covered","Gap") -> Covered
A33: FR-D-007 | B33: Maintain Laboratory Test Catalogue | C33: =COUNTIF('API Endpoints'!$K$4:$K$92,"*FR-D-007*") -> 3 | D33: =IF(C33>0,"Covered","Gap") -> Covered
A34: FR-E-001 | B34: Maintain Price List | C34: =COUNTIF('API Endpoints'!$K$4:$K$92,"*FR-E-001*") -> 3 | D34: =IF(C34>0,"Covered","Gap") -> Covered
A35: FR-E-002 | B35: Generate Bill | C35: =COUNTIF('API Endpoints'!$K$4:$K$92,"*FR-E-002*") -> 4 | D35: =IF(C35>0,"Covered","Gap") -> Covered
A36: FR-E-003 | B36: Bill Status Management | C36: =COUNTIF('API Endpoints'!$K$4:$K$92,"*FR-E-003*") -> 2 | D36: =IF(C36>0,"Covered","Gap") -> Covered
A37: FR-E-004 | B37: Record Payment | C37: =COUNTIF('API Endpoints'!$K$4:$K$92,"*FR-E-004*") -> 2 | D37: =IF(C37>0,"Covered","Gap") -> Covered
A38: FR-E-005 | B38: Manage Insurance Details | C38: =COUNTIF('API Endpoints'!$K$4:$K$92,"*FR-E-005*") -> 2 | D38: =IF(C38>0,"Covered","Gap") -> Covered
A39: FR-E-006 | B39: Print Bill and Receipt | C39: =COUNTIF('API Endpoints'!$K$4:$K$92,"*FR-E-006*") -> 1 | D39: =IF(C39>0,"Covered","Gap") -> Covered
A40: FR-E-007 | B40: View Daily Collections | C40: =COUNTIF('API Endpoints'!$K$4:$K$92,"*FR-E-007*") -> 1 | D40: =IF(C40>0,"Covered","Gap") -> Covered
A41: FR-F-001 | B41: User Login and Role-Based Access | C41: =COUNTIF('API Endpoints'!$K$4:$K$92,"*FR-F-001*") -> 3 | D41: =IF(C41>0,"Covered","Gap") -> Covered
...
